2025-03-20 14:12:14.110 [ERROR]  werkzeug                        Error on request:
Traceback (most recent call last):
  File "/home/self-clearing/venv/lib/python3.11/site-packages/werkzeug/serving.py", line 363, in run_wsgi
    execute(self.server.app)
  File "/home/self-clearing/venv/lib/python3.11/site-packages/werkzeug/serving.py", line 326, in execute
    for data in application_iter:
  File "/home/self-clearing/venv/lib/python3.11/site-packages/werkzeug/wsgi.py", line 256, in __next__
    return self._next()
           ^^^^^^^^^^^^
  File "/home/self-clearing/venv/lib/python3.11/site-packages/werkzeug/wrappers/response.py", line 32, in _iter_encoded
    for item in iterable:
  File "/home/self-clearing/Self_Clearing_Server/server/views/camera_1.py", line 36, in gen_frames_1
    if not stop_event.is_set():
           ^^^^^^^^^^^^^^^^^^^^
AttributeError: 'bool' object has no attribute 'is_set'  
2025-03-20 14:16:37.677 [ERROR]  werkzeug                        Error on request:
Traceback (most recent call last):
  File "/home/self-clearing/venv/lib/python3.11/site-packages/werkzeug/serving.py", line 363, in run_wsgi
    execute(self.server.app)
  File "/home/self-clearing/venv/lib/python3.11/site-packages/werkzeug/serving.py", line 326, in execute
    for data in application_iter:
  File "/home/self-clearing/venv/lib/python3.11/site-packages/werkzeug/wsgi.py", line 256, in __next__
    return self._next()
           ^^^^^^^^^^^^
  File "/home/self-clearing/venv/lib/python3.11/site-packages/werkzeug/wrappers/response.py", line 32, in _iter_encoded
    for item in iterable:
  File "/home/self-clearing/Self_Clearing_Server/server/views/camera_1.py", line 36, in gen_frames_1
    if stop_event.is_set():
       ^^^^^^^^^^^^^^^^^^^^
AttributeError: 'bool' object has no attribute 'is_set'  
2025-03-20 14:18:34.243 [ERROR]  werkzeug                        Error on request:
Traceback (most recent call last):
  File "/home/self-clearing/venv/lib/python3.11/site-packages/werkzeug/serving.py", line 363, in run_wsgi
    execute(self.server.app)
  File "/home/self-clearing/venv/lib/python3.11/site-packages/werkzeug/serving.py", line 324, in execute
    application_iter = app(environ, start_response)
                       ^^^^^^^^^^^^^^^^^^^^^^^^^^^^
  File "/home/self-clearing/venv/lib/python3.11/site-packages/flask/app.py", line 1498, in __call__
    return self.wsgi_app(environ, start_response)
           ^^^^^^^^^^^^^^^^^^^^^^^^^^^^^^^^^^^^^^
  File "/home/self-clearing/venv/lib/python3.11/site-packages/flask_socketio/__init__.py", line 43, in __call__
    return super(_SocketIOMiddleware, self).__call__(environ,
           ^^^^^^^^^^^^^^^^^^^^^^^^^^^^^^^^^^^^^^^^^^^^^^^^^^
  File "/home/self-clearing/venv/lib/python3.11/site-packages/engineio/middleware.py", line 63, in __call__
    return self.engineio_app.handle_request(environ, start_response)
           ^^^^^^^^^^^^^^^^^^^^^^^^^^^^^^^^^^^^^^^^^^^^^^^^^^^^^^^^^
  File "/home/self-clearing/venv/lib/python3.11/site-packages/socketio/server.py", line 433, in handle_request
    return self.eio.handle_request(environ, start_response)
           ^^^^^^^^^^^^^^^^^^^^^^^^^^^^^^^^^^^^^^^^^^^^^^^^
  File "/home/self-clearing/venv/lib/python3.11/site-packages/engineio/server.py", line 272, in handle_request
    socket = self._get_socket(sid)
             ^^^^^^^^^^^^^^^^^^^^^
  File "/home/self-clearing/venv/lib/python3.11/site-packages/engineio/base_server.py", line 229, in _get_socket
    raise KeyError('Session is disconnected')
KeyError: 'Session is disconnected'  
2025-03-20 14:18:35.677 [ERROR]  werkzeug                        Error on request:
Traceback (most recent call last):
  File "/home/self-clearing/venv/lib/python3.11/site-packages/werkzeug/serving.py", line 363, in run_wsgi
    execute(self.server.app)
  File "/home/self-clearing/venv/lib/python3.11/site-packages/werkzeug/serving.py", line 326, in execute
    for data in application_iter:
  File "/home/self-clearing/venv/lib/python3.11/site-packages/werkzeug/wsgi.py", line 256, in __next__
    return self._next()
           ^^^^^^^^^^^^
  File "/home/self-clearing/venv/lib/python3.11/site-packages/werkzeug/wrappers/response.py", line 32, in _iter_encoded
    for item in iterable:
  File "/home/self-clearing/Self_Clearing_Server/server/views/camera_1.py", line 36, in gen_frames_1
    if not stop_event.is_set():
           ^^^^^^^^^^^^^^^^^^^^
AttributeError: 'bool' object has no attribute 'is_set'  
2025-03-20 14:19:33.905 [ERROR]  werkzeug                        Error on request:
Traceback (most recent call last):
  File "/home/self-clearing/venv/lib/python3.11/site-packages/werkzeug/serving.py", line 363, in run_wsgi
    execute(self.server.app)
  File "/home/self-clearing/venv/lib/python3.11/site-packages/werkzeug/serving.py", line 324, in execute
    application_iter = app(environ, start_response)
                       ^^^^^^^^^^^^^^^^^^^^^^^^^^^^
  File "/home/self-clearing/venv/lib/python3.11/site-packages/flask/app.py", line 1498, in __call__
    return self.wsgi_app(environ, start_response)
           ^^^^^^^^^^^^^^^^^^^^^^^^^^^^^^^^^^^^^^
  File "/home/self-clearing/venv/lib/python3.11/site-packages/flask_socketio/__init__.py", line 43, in __call__
    return super(_SocketIOMiddleware, self).__call__(environ,
           ^^^^^^^^^^^^^^^^^^^^^^^^^^^^^^^^^^^^^^^^^^^^^^^^^^
  File "/home/self-clearing/venv/lib/python3.11/site-packages/engineio/middleware.py", line 63, in __call__
    return self.engineio_app.handle_request(environ, start_response)
           ^^^^^^^^^^^^^^^^^^^^^^^^^^^^^^^^^^^^^^^^^^^^^^^^^^^^^^^^^
  File "/home/self-clearing/venv/lib/python3.11/site-packages/socketio/server.py", line 433, in handle_request
    return self.eio.handle_request(environ, start_response)
           ^^^^^^^^^^^^^^^^^^^^^^^^^^^^^^^^^^^^^^^^^^^^^^^^
  File "/home/self-clearing/venv/lib/python3.11/site-packages/engineio/server.py", line 272, in handle_request
    socket = self._get_socket(sid)
             ^^^^^^^^^^^^^^^^^^^^^
  File "/home/self-clearing/venv/lib/python3.11/site-packages/engineio/base_server.py", line 229, in _get_socket
    raise KeyError('Session is disconnected')
KeyError: 'Session is disconnected'  
2025-03-20 14:34:52.227 [ERROR]  werkzeug                        Error on request:
Traceback (most recent call last):
  File "/home/self-clearing/venv/lib/python3.11/site-packages/werkzeug/serving.py", line 363, in run_wsgi
    execute(self.server.app)
  File "/home/self-clearing/venv/lib/python3.11/site-packages/werkzeug/serving.py", line 324, in execute
    application_iter = app(environ, start_response)
                       ^^^^^^^^^^^^^^^^^^^^^^^^^^^^
  File "/home/self-clearing/venv/lib/python3.11/site-packages/flask/app.py", line 1498, in __call__
    return self.wsgi_app(environ, start_response)
           ^^^^^^^^^^^^^^^^^^^^^^^^^^^^^^^^^^^^^^
  File "/home/self-clearing/venv/lib/python3.11/site-packages/flask_socketio/__init__.py", line 43, in __call__
    return super(_SocketIOMiddleware, self).__call__(environ,
           ^^^^^^^^^^^^^^^^^^^^^^^^^^^^^^^^^^^^^^^^^^^^^^^^^^
  File "/home/self-clearing/venv/lib/python3.11/site-packages/engineio/middleware.py", line 63, in __call__
    return self.engineio_app.handle_request(environ, start_response)
           ^^^^^^^^^^^^^^^^^^^^^^^^^^^^^^^^^^^^^^^^^^^^^^^^^^^^^^^^^
  File "/home/self-clearing/venv/lib/python3.11/site-packages/socketio/server.py", line 433, in handle_request
    return self.eio.handle_request(environ, start_response)
           ^^^^^^^^^^^^^^^^^^^^^^^^^^^^^^^^^^^^^^^^^^^^^^^^
  File "/home/self-clearing/venv/lib/python3.11/site-packages/engineio/server.py", line 272, in handle_request
    socket = self._get_socket(sid)
             ^^^^^^^^^^^^^^^^^^^^^
  File "/home/self-clearing/venv/lib/python3.11/site-packages/engineio/base_server.py", line 229, in _get_socket
    raise KeyError('Session is disconnected')
KeyError: 'Session is disconnected'  
2025-03-20 14:51:08.912 [ERROR]  server                          Exception on /camera_1 [POST]  
Traceback (most recent call last):
  File "/home/self-clearing/venv/lib/python3.11/site-packages/flask/app.py", line 1473, in wsgi_app
    response = self.full_dispatch_request()
               ^^^^^^^^^^^^^^^^^^^^^^^^^^^^
  File "/home/self-clearing/venv/lib/python3.11/site-packages/flask/app.py", line 882, in full_dispatch_request
    rv = self.handle_user_exception(e)
         ^^^^^^^^^^^^^^^^^^^^^^^^^^^^^
  File "/home/self-clearing/venv/lib/python3.11/site-packages/flask/app.py", line 880, in full_dispatch_request
    rv = self.dispatch_request()
         ^^^^^^^^^^^^^^^^^^^^^^^
  File "/home/self-clearing/venv/lib/python3.11/site-packages/flask/app.py", line 865, in dispatch_request
    return self.ensure_sync(self.view_functions[rule.endpoint])(**view_args)  # type: ignore[no-any-return]
           ^^^^^^^^^^^^^^^^^^^^^^^^^^^^^^^^^^^^^^^^^^^^^^^^^^^^^^^^^^^^^^^^^
  File "/home/self-clearing/Self_Clearing_Server/server/views/camera_1.py", line 80, in timelapse1
    timelapse_on = not timelapse_on
                       ^^^^^^^^^^^^
UnboundLocalError: cannot access local variable 'timelapse_on' where it is not associated with a value
2025-03-20 14:53:08.985 [ERROR]  werkzeug                        Error on request:
Traceback (most recent call last):
  File "/home/self-clearing/venv/lib/python3.11/site-packages/werkzeug/serving.py", line 363, in run_wsgi
    execute(self.server.app)
  File "/home/self-clearing/venv/lib/python3.11/site-packages/werkzeug/serving.py", line 324, in execute
    application_iter = app(environ, start_response)
                       ^^^^^^^^^^^^^^^^^^^^^^^^^^^^
  File "/home/self-clearing/venv/lib/python3.11/site-packages/flask/app.py", line 1498, in __call__
    return self.wsgi_app(environ, start_response)
           ^^^^^^^^^^^^^^^^^^^^^^^^^^^^^^^^^^^^^^
  File "/home/self-clearing/venv/lib/python3.11/site-packages/flask_socketio/__init__.py", line 43, in __call__
    return super(_SocketIOMiddleware, self).__call__(environ,
           ^^^^^^^^^^^^^^^^^^^^^^^^^^^^^^^^^^^^^^^^^^^^^^^^^^
  File "/home/self-clearing/venv/lib/python3.11/site-packages/engineio/middleware.py", line 63, in __call__
    return self.engineio_app.handle_request(environ, start_response)
           ^^^^^^^^^^^^^^^^^^^^^^^^^^^^^^^^^^^^^^^^^^^^^^^^^^^^^^^^^
  File "/home/self-clearing/venv/lib/python3.11/site-packages/socketio/server.py", line 433, in handle_request
    return self.eio.handle_request(environ, start_response)
           ^^^^^^^^^^^^^^^^^^^^^^^^^^^^^^^^^^^^^^^^^^^^^^^^
  File "/home/self-clearing/venv/lib/python3.11/site-packages/engineio/server.py", line 272, in handle_request
    socket = self._get_socket(sid)
             ^^^^^^^^^^^^^^^^^^^^^
  File "/home/self-clearing/venv/lib/python3.11/site-packages/engineio/base_server.py", line 229, in _get_socket
    raise KeyError('Session is disconnected')
KeyError: 'Session is disconnected'  
2025-03-20 14:53:17.009 [ERROR]  server                          Exception on /camera_1 [POST]  
Traceback (most recent call last):
  File "/home/self-clearing/venv/lib/python3.11/site-packages/flask/app.py", line 1473, in wsgi_app
    response = self.full_dispatch_request()
               ^^^^^^^^^^^^^^^^^^^^^^^^^^^^
  File "/home/self-clearing/venv/lib/python3.11/site-packages/flask/app.py", line 882, in full_dispatch_request
    rv = self.handle_user_exception(e)
         ^^^^^^^^^^^^^^^^^^^^^^^^^^^^^
  File "/home/self-clearing/venv/lib/python3.11/site-packages/flask/app.py", line 880, in full_dispatch_request
    rv = self.dispatch_request()
         ^^^^^^^^^^^^^^^^^^^^^^^
  File "/home/self-clearing/venv/lib/python3.11/site-packages/flask/app.py", line 865, in dispatch_request
    return self.ensure_sync(self.view_functions[rule.endpoint])(**view_args)  # type: ignore[no-any-return]
           ^^^^^^^^^^^^^^^^^^^^^^^^^^^^^^^^^^^^^^^^^^^^^^^^^^^^^^^^^^^^^^^^^
  File "/home/self-clearing/Self_Clearing_Server/server/views/camera_1.py", line 89, in timelapse1
    if (timelapse_on == True):
        ^^^^^^^^^^^^
NameError: name 'timelapse_on' is not defined
2025-03-20 14:53:32.938 [ERROR]  werkzeug                        Error on request:
Traceback (most recent call last):
  File "/home/self-clearing/venv/lib/python3.11/site-packages/werkzeug/serving.py", line 363, in run_wsgi
    execute(self.server.app)
  File "/home/self-clearing/venv/lib/python3.11/site-packages/werkzeug/serving.py", line 324, in execute
    application_iter = app(environ, start_response)
                       ^^^^^^^^^^^^^^^^^^^^^^^^^^^^
  File "/home/self-clearing/venv/lib/python3.11/site-packages/flask/app.py", line 1498, in __call__
    return self.wsgi_app(environ, start_response)
           ^^^^^^^^^^^^^^^^^^^^^^^^^^^^^^^^^^^^^^
  File "/home/self-clearing/venv/lib/python3.11/site-packages/flask_socketio/__init__.py", line 43, in __call__
    return super(_SocketIOMiddleware, self).__call__(environ,
           ^^^^^^^^^^^^^^^^^^^^^^^^^^^^^^^^^^^^^^^^^^^^^^^^^^
  File "/home/self-clearing/venv/lib/python3.11/site-packages/engineio/middleware.py", line 63, in __call__
    return self.engineio_app.handle_request(environ, start_response)
           ^^^^^^^^^^^^^^^^^^^^^^^^^^^^^^^^^^^^^^^^^^^^^^^^^^^^^^^^^
  File "/home/self-clearing/venv/lib/python3.11/site-packages/socketio/server.py", line 433, in handle_request
    return self.eio.handle_request(environ, start_response)
           ^^^^^^^^^^^^^^^^^^^^^^^^^^^^^^^^^^^^^^^^^^^^^^^^
  File "/home/self-clearing/venv/lib/python3.11/site-packages/engineio/server.py", line 272, in handle_request
    socket = self._get_socket(sid)
             ^^^^^^^^^^^^^^^^^^^^^
  File "/home/self-clearing/venv/lib/python3.11/site-packages/engineio/base_server.py", line 229, in _get_socket
    raise KeyError('Session is disconnected')
KeyError: 'Session is disconnected'  
2025-03-20 14:57:31.477 [ERROR]  werkzeug                        Error on request:
Traceback (most recent call last):
  File "/home/self-clearing/venv/lib/python3.11/site-packages/werkzeug/serving.py", line 363, in run_wsgi
    execute(self.server.app)
  File "/home/self-clearing/venv/lib/python3.11/site-packages/werkzeug/serving.py", line 324, in execute
    application_iter = app(environ, start_response)
                       ^^^^^^^^^^^^^^^^^^^^^^^^^^^^
  File "/home/self-clearing/venv/lib/python3.11/site-packages/flask/app.py", line 1498, in __call__
    return self.wsgi_app(environ, start_response)
           ^^^^^^^^^^^^^^^^^^^^^^^^^^^^^^^^^^^^^^
  File "/home/self-clearing/venv/lib/python3.11/site-packages/flask_socketio/__init__.py", line 43, in __call__
    return super(_SocketIOMiddleware, self).__call__(environ,
           ^^^^^^^^^^^^^^^^^^^^^^^^^^^^^^^^^^^^^^^^^^^^^^^^^^
  File "/home/self-clearing/venv/lib/python3.11/site-packages/engineio/middleware.py", line 63, in __call__
    return self.engineio_app.handle_request(environ, start_response)
           ^^^^^^^^^^^^^^^^^^^^^^^^^^^^^^^^^^^^^^^^^^^^^^^^^^^^^^^^^
  File "/home/self-clearing/venv/lib/python3.11/site-packages/socketio/server.py", line 433, in handle_request
    return self.eio.handle_request(environ, start_response)
           ^^^^^^^^^^^^^^^^^^^^^^^^^^^^^^^^^^^^^^^^^^^^^^^^
  File "/home/self-clearing/venv/lib/python3.11/site-packages/engineio/server.py", line 272, in handle_request
    socket = self._get_socket(sid)
             ^^^^^^^^^^^^^^^^^^^^^
  File "/home/self-clearing/venv/lib/python3.11/site-packages/engineio/base_server.py", line 229, in _get_socket
    raise KeyError('Session is disconnected')
KeyError: 'Session is disconnected'  
2025-03-20 16:02:50.965 [ERROR]  werkzeug                        Error on request:
Traceback (most recent call last):
  File "/home/self-clearing/venv/lib/python3.11/site-packages/werkzeug/serving.py", line 363, in run_wsgi
    execute(self.server.app)
  File "/home/self-clearing/venv/lib/python3.11/site-packages/werkzeug/serving.py", line 324, in execute
    application_iter = app(environ, start_response)
                       ^^^^^^^^^^^^^^^^^^^^^^^^^^^^
  File "/home/self-clearing/venv/lib/python3.11/site-packages/flask/app.py", line 1498, in __call__
    return self.wsgi_app(environ, start_response)
           ^^^^^^^^^^^^^^^^^^^^^^^^^^^^^^^^^^^^^^
  File "/home/self-clearing/venv/lib/python3.11/site-packages/flask_socketio/__init__.py", line 43, in __call__
    return super(_SocketIOMiddleware, self).__call__(environ,
           ^^^^^^^^^^^^^^^^^^^^^^^^^^^^^^^^^^^^^^^^^^^^^^^^^^
  File "/home/self-clearing/venv/lib/python3.11/site-packages/engineio/middleware.py", line 63, in __call__
    return self.engineio_app.handle_request(environ, start_response)
           ^^^^^^^^^^^^^^^^^^^^^^^^^^^^^^^^^^^^^^^^^^^^^^^^^^^^^^^^^
  File "/home/self-clearing/venv/lib/python3.11/site-packages/socketio/server.py", line 433, in handle_request
    return self.eio.handle_request(environ, start_response)
           ^^^^^^^^^^^^^^^^^^^^^^^^^^^^^^^^^^^^^^^^^^^^^^^^
  File "/home/self-clearing/venv/lib/python3.11/site-packages/engineio/server.py", line 272, in handle_request
    socket = self._get_socket(sid)
             ^^^^^^^^^^^^^^^^^^^^^
  File "/home/self-clearing/venv/lib/python3.11/site-packages/engineio/base_server.py", line 229, in _get_socket
    raise KeyError('Session is disconnected')
KeyError: 'Session is disconnected'  
