2025-03-24 12:50:13.619 [ERROR]  server                          Exception on /camera_1/video_feed [GET]  
Traceback (most recent call last):
  File "/home/self-clearing/venv/lib/python3.11/site-packages/flask/app.py", line 1473, in wsgi_app
    response = self.full_dispatch_request()
               ^^^^^^^^^^^^^^^^^^^^^^^^^^^^
  File "/home/self-clearing/venv/lib/python3.11/site-packages/flask/app.py", line 882, in full_dispatch_request
    rv = self.handle_user_exception(e)
         ^^^^^^^^^^^^^^^^^^^^^^^^^^^^^
  File "/home/self-clearing/venv/lib/python3.11/site-packages/flask/app.py", line 880, in full_dispatch_request
    rv = self.dispatch_request()
         ^^^^^^^^^^^^^^^^^^^^^^^
  File "/home/self-clearing/venv/lib/python3.11/site-packages/flask/app.py", line 865, in dispatch_request
    return self.ensure_sync(self.view_functions[rule.endpoint])(**view_args)  # type: ignore[no-any-return]
           ^^^^^^^^^^^^^^^^^^^^^^^^^^^^^^^^^^^^^^^^^^^^^^^^^^^^^^^^^^^^^^^^^
  File "/home/self-clearing/Self_Clearing_Server/server/views/camera_1.py", line 104, in video_feed
    return Response(camera_control_1.yield_frame(), mimetype="multipart/x-mixed-replace; boundary=frame")
                 ^^^^^^^^^^^^^^^^^^^^^^^^^^^^^^
TypeError: microscope_camera_control.yield_frame() missing 1 required positional argument: 'self'
2025-03-24 12:50:55.679 [ERROR]  werkzeug                        Error on request:
Traceback (most recent call last):
  File "/home/self-clearing/venv/lib/python3.11/site-packages/werkzeug/serving.py", line 363, in run_wsgi
    execute(self.server.app)
  File "/home/self-clearing/venv/lib/python3.11/site-packages/werkzeug/serving.py", line 326, in execute
    for data in application_iter:
  File "/home/self-clearing/venv/lib/python3.11/site-packages/werkzeug/wsgi.py", line 256, in __next__
    return self._next()
           ^^^^^^^^^^^^
  File "/home/self-clearing/venv/lib/python3.11/site-packages/werkzeug/wrappers/response.py", line 32, in _iter_encoded
    for item in iterable:
  File "/home/self-clearing/Self_Clearing_Server/server/views/camera_1.py", line 58, in yield_frame
    yield (b"--frame\r\n" b"Content-Type: image/jpeg\r\n\r\n" + self.frame_to_display + b"\r\n")
                                                                ^^^^^^^^^^^^^^^^^^^^^^^^^^^^^^^^
AttributeError: type object 'microscope_camera_control' has no attribute 'frame_to_display'  
2025-03-24 12:51:51.030 [ERROR]  werkzeug                        Error on request:
Traceback (most recent call last):
  File "/home/self-clearing/venv/lib/python3.11/site-packages/werkzeug/serving.py", line 363, in run_wsgi
    execute(self.server.app)
  File "/home/self-clearing/venv/lib/python3.11/site-packages/werkzeug/serving.py", line 326, in execute
    for data in application_iter:
  File "/home/self-clearing/venv/lib/python3.11/site-packages/werkzeug/wsgi.py", line 256, in __next__
    return self._next()
           ^^^^^^^^^^^^
  File "/home/self-clearing/venv/lib/python3.11/site-packages/werkzeug/wrappers/response.py", line 32, in _iter_encoded
    for item in iterable:
  File "/home/self-clearing/Self_Clearing_Server/server/views/camera_1.py", line 58, in yield_frame
    yield (b"--frame\r\n" b"Content-Type: image/jpeg\r\n\r\n" + self.frame_to_display + b"\r\n")
                                                                ^^^^^^^^^^^^^^^^^^^^^^^^^^^^^^^^
AttributeError: type object 'microscope_camera_control' has no attribute 'frame_to_display'  
2025-03-24 12:53:42.849 [ERROR]  server                          Exception on /camera_1/video_feed [GET]  
Traceback (most recent call last):
  File "/home/self-clearing/venv/lib/python3.11/site-packages/flask/app.py", line 1473, in wsgi_app
    response = self.full_dispatch_request()
               ^^^^^^^^^^^^^^^^^^^^^^^^^^^^
  File "/home/self-clearing/venv/lib/python3.11/site-packages/flask/app.py", line 882, in full_dispatch_request
    rv = self.handle_user_exception(e)
         ^^^^^^^^^^^^^^^^^^^^^^^^^^^^^
  File "/home/self-clearing/venv/lib/python3.11/site-packages/flask/app.py", line 880, in full_dispatch_request
    rv = self.dispatch_request()
         ^^^^^^^^^^^^^^^^^^^^^^^
  File "/home/self-clearing/venv/lib/python3.11/site-packages/flask/app.py", line 865, in dispatch_request
    return self.ensure_sync(self.view_functions[rule.endpoint])(**view_args)  # type: ignore[no-any-return]
           ^^^^^^^^^^^^^^^^^^^^^^^^^^^^^^^^^^^^^^^^^^^^^^^^^^^^^^^^^^^^^^^^^
  File "/home/self-clearing/Self_Clearing_Server/server/views/camera_1.py", line 102, in video_feed
    return Response(camera_control_1.yield_frame(camera_control_1), mimetype="multipart/x-mixed-replace; boundary=frame")
                 ^^^^^^^^^^^^^^^^
NameError: name 'camera_control_1' is not defined
2025-03-24 12:54:02.968 [ERROR]  werkzeug                        Error on request:
Traceback (most recent call last):
  File "/home/self-clearing/venv/lib/python3.11/site-packages/werkzeug/serving.py", line 363, in run_wsgi
    execute(self.server.app)
  File "/home/self-clearing/venv/lib/python3.11/site-packages/werkzeug/serving.py", line 326, in execute
    for data in application_iter:
  File "/home/self-clearing/venv/lib/python3.11/site-packages/werkzeug/wsgi.py", line 256, in __next__
    return self._next()
           ^^^^^^^^^^^^
  File "/home/self-clearing/venv/lib/python3.11/site-packages/werkzeug/wrappers/response.py", line 32, in _iter_encoded
    for item in iterable:
  File "/home/self-clearing/Self_Clearing_Server/server/views/camera_1.py", line 58, in yield_frame
    yield (b"--frame\r\n" b"Content-Type: image/jpeg\r\n\r\n" + self.frame_to_display + b"\r\n")
                                                                ^^^^^^^^^^^^^^^^^^^^^^^^^^^^^^^^
AttributeError: type object 'microscope_camera_control' has no attribute 'frame_to_display'  
2025-03-24 12:55:13.947 [ERROR]  server                          Exception on /camera_1/video_feed [GET]  
Traceback (most recent call last):
  File "/home/self-clearing/venv/lib/python3.11/site-packages/flask/app.py", line 1473, in wsgi_app
    response = self.full_dispatch_request()
               ^^^^^^^^^^^^^^^^^^^^^^^^^^^^
  File "/home/self-clearing/venv/lib/python3.11/site-packages/flask/app.py", line 882, in full_dispatch_request
    rv = self.handle_user_exception(e)
         ^^^^^^^^^^^^^^^^^^^^^^^^^^^^^
  File "/home/self-clearing/venv/lib/python3.11/site-packages/flask/app.py", line 880, in full_dispatch_request
    rv = self.dispatch_request()
         ^^^^^^^^^^^^^^^^^^^^^^^
  File "/home/self-clearing/venv/lib/python3.11/site-packages/flask/app.py", line 865, in dispatch_request
    return self.ensure_sync(self.view_functions[rule.endpoint])(**view_args)  # type: ignore[no-any-return]
           ^^^^^^^^^^^^^^^^^^^^^^^^^^^^^^^^^^^^^^^^^^^^^^^^^^^^^^^^^^^^^^^^^
  File "/home/self-clearing/Self_Clearing_Server/server/views/camera_1.py", line 103, in video_feed
    return Response(camera_control_1.yield_frame(camera_control_1), mimetype="multipart/x-mixed-replace; boundary=frame")
                 ^^^^^^^^^^^^^^^^^^^^^^^^^^^^^^^^^^^^^^^^^^^^^^
TypeError: microscope_camera_control.yield_frame() takes 1 positional argument but 2 were given
2025-03-24 12:55:14.725 [ERROR]  server                          Exception on /camera_1/video_feed [GET]  
Traceback (most recent call last):
  File "/home/self-clearing/venv/lib/python3.11/site-packages/flask/app.py", line 1473, in wsgi_app
    response = self.full_dispatch_request()
               ^^^^^^^^^^^^^^^^^^^^^^^^^^^^
  File "/home/self-clearing/venv/lib/python3.11/site-packages/flask/app.py", line 882, in full_dispatch_request
    rv = self.handle_user_exception(e)
         ^^^^^^^^^^^^^^^^^^^^^^^^^^^^^
  File "/home/self-clearing/venv/lib/python3.11/site-packages/flask/app.py", line 880, in full_dispatch_request
    rv = self.dispatch_request()
         ^^^^^^^^^^^^^^^^^^^^^^^
  File "/home/self-clearing/venv/lib/python3.11/site-packages/flask/app.py", line 865, in dispatch_request
    return self.ensure_sync(self.view_functions[rule.endpoint])(**view_args)  # type: ignore[no-any-return]
           ^^^^^^^^^^^^^^^^^^^^^^^^^^^^^^^^^^^^^^^^^^^^^^^^^^^^^^^^^^^^^^^^^
  File "/home/self-clearing/Self_Clearing_Server/server/views/camera_1.py", line 103, in video_feed
    return Response(camera_control_1.yield_frame(camera_control_1), mimetype="multipart/x-mixed-replace; boundary=frame")
                 ^^^^^^^^^^^^^^^^^^^^^^^^^^^^^^^^^^^^^^^^^^^^^^
TypeError: microscope_camera_control.yield_frame() takes 1 positional argument but 2 were given
2025-03-24 12:56:48.287 [ERROR]  server                          Exception on /camera_1/video_feed [GET]  
Traceback (most recent call last):
  File "/home/self-clearing/venv/lib/python3.11/site-packages/flask/app.py", line 1473, in wsgi_app
    response = self.full_dispatch_request()
               ^^^^^^^^^^^^^^^^^^^^^^^^^^^^
  File "/home/self-clearing/venv/lib/python3.11/site-packages/flask/app.py", line 882, in full_dispatch_request
    rv = self.handle_user_exception(e)
         ^^^^^^^^^^^^^^^^^^^^^^^^^^^^^
  File "/home/self-clearing/venv/lib/python3.11/site-packages/flask/app.py", line 880, in full_dispatch_request
    rv = self.dispatch_request()
         ^^^^^^^^^^^^^^^^^^^^^^^
  File "/home/self-clearing/venv/lib/python3.11/site-packages/flask/app.py", line 865, in dispatch_request
    return self.ensure_sync(self.view_functions[rule.endpoint])(**view_args)  # type: ignore[no-any-return]
           ^^^^^^^^^^^^^^^^^^^^^^^^^^^^^^^^^^^^^^^^^^^^^^^^^^^^^^^^^^^^^^^^^
  File "/home/self-clearing/Self_Clearing_Server/server/views/camera_1.py", line 103, in video_feed
    return Response(camera_control_1.yield_frame(camera_control_1), mimetype="multipart/x-mixed-replace; boundary=frame")
                 ^^^^^^^^^^^^^^^^^^^^^^^^^^^^^^^^^^^^^^^^^^^^^^
TypeError: microscope_camera_control.yield_frame() takes 1 positional argument but 2 were given
2025-03-24 12:56:51.650 [ERROR]  server                          Exception on /camera_1/video_feed [GET]  
Traceback (most recent call last):
  File "/home/self-clearing/venv/lib/python3.11/site-packages/flask/app.py", line 1473, in wsgi_app
    response = self.full_dispatch_request()
               ^^^^^^^^^^^^^^^^^^^^^^^^^^^^
  File "/home/self-clearing/venv/lib/python3.11/site-packages/flask/app.py", line 882, in full_dispatch_request
    rv = self.handle_user_exception(e)
         ^^^^^^^^^^^^^^^^^^^^^^^^^^^^^
  File "/home/self-clearing/venv/lib/python3.11/site-packages/flask/app.py", line 880, in full_dispatch_request
    rv = self.dispatch_request()
         ^^^^^^^^^^^^^^^^^^^^^^^
  File "/home/self-clearing/venv/lib/python3.11/site-packages/flask/app.py", line 865, in dispatch_request
    return self.ensure_sync(self.view_functions[rule.endpoint])(**view_args)  # type: ignore[no-any-return]
           ^^^^^^^^^^^^^^^^^^^^^^^^^^^^^^^^^^^^^^^^^^^^^^^^^^^^^^^^^^^^^^^^^
  File "/home/self-clearing/Self_Clearing_Server/server/views/camera_1.py", line 103, in video_feed
    return Response(camera_control_1.yield_frame(camera_control_1), mimetype="multipart/x-mixed-replace; boundary=frame")
                 ^^^^^^^^^^^^^^^^^^^^^^^^^^^^^^^^^^^^^^^^^^^^^^
TypeError: microscope_camera_control.yield_frame() takes 1 positional argument but 2 were given
2025-03-24 12:57:11.245 [ERROR]  server                          Exception on /camera_1/video_feed [GET]  
Traceback (most recent call last):
  File "/home/self-clearing/venv/lib/python3.11/site-packages/flask/app.py", line 1473, in wsgi_app
    response = self.full_dispatch_request()
               ^^^^^^^^^^^^^^^^^^^^^^^^^^^^
  File "/home/self-clearing/venv/lib/python3.11/site-packages/flask/app.py", line 882, in full_dispatch_request
    rv = self.handle_user_exception(e)
         ^^^^^^^^^^^^^^^^^^^^^^^^^^^^^
  File "/home/self-clearing/venv/lib/python3.11/site-packages/flask/app.py", line 880, in full_dispatch_request
    rv = self.dispatch_request()
         ^^^^^^^^^^^^^^^^^^^^^^^
  File "/home/self-clearing/venv/lib/python3.11/site-packages/flask/app.py", line 865, in dispatch_request
    return self.ensure_sync(self.view_functions[rule.endpoint])(**view_args)  # type: ignore[no-any-return]
           ^^^^^^^^^^^^^^^^^^^^^^^^^^^^^^^^^^^^^^^^^^^^^^^^^^^^^^^^^^^^^^^^^
  File "/home/self-clearing/Self_Clearing_Server/server/views/camera_1.py", line 103, in video_feed
    return Response(camera_control_1.yield_frame(camera_control_1), mimetype="multipart/x-mixed-replace; boundary=frame")
                 ^^^^^^^^^^^^^^^^^^^^^^^^^^^^^^^^^^^^^^^^^^^^^^
TypeError: microscope_camera_control.yield_frame() takes 1 positional argument but 2 were given
2025-03-24 13:01:48.702 [ERROR]  werkzeug                        Error on request:
Traceback (most recent call last):
  File "/home/self-clearing/venv/lib/python3.11/site-packages/werkzeug/serving.py", line 363, in run_wsgi
    execute(self.server.app)
  File "/home/self-clearing/venv/lib/python3.11/site-packages/werkzeug/serving.py", line 324, in execute
    application_iter = app(environ, start_response)
                       ^^^^^^^^^^^^^^^^^^^^^^^^^^^^
  File "/home/self-clearing/venv/lib/python3.11/site-packages/flask/app.py", line 1498, in __call__
    return self.wsgi_app(environ, start_response)
           ^^^^^^^^^^^^^^^^^^^^^^^^^^^^^^^^^^^^^^
  File "/home/self-clearing/venv/lib/python3.11/site-packages/flask_socketio/__init__.py", line 43, in __call__
    return super(_SocketIOMiddleware, self).__call__(environ,
           ^^^^^^^^^^^^^^^^^^^^^^^^^^^^^^^^^^^^^^^^^^^^^^^^^^
  File "/home/self-clearing/venv/lib/python3.11/site-packages/engineio/middleware.py", line 63, in __call__
    return self.engineio_app.handle_request(environ, start_response)
           ^^^^^^^^^^^^^^^^^^^^^^^^^^^^^^^^^^^^^^^^^^^^^^^^^^^^^^^^^
  File "/home/self-clearing/venv/lib/python3.11/site-packages/socketio/server.py", line 433, in handle_request
    return self.eio.handle_request(environ, start_response)
           ^^^^^^^^^^^^^^^^^^^^^^^^^^^^^^^^^^^^^^^^^^^^^^^^
  File "/home/self-clearing/venv/lib/python3.11/site-packages/engineio/server.py", line 272, in handle_request
    socket = self._get_socket(sid)
             ^^^^^^^^^^^^^^^^^^^^^
  File "/home/self-clearing/venv/lib/python3.11/site-packages/engineio/base_server.py", line 229, in _get_socket
    raise KeyError('Session is disconnected')
KeyError: 'Session is disconnected'  
2025-03-24 13:03:28.755 [ERROR]  werkzeug                        Error on request:
Traceback (most recent call last):
  File "/home/self-clearing/venv/lib/python3.11/site-packages/werkzeug/serving.py", line 363, in run_wsgi
    execute(self.server.app)
  File "/home/self-clearing/venv/lib/python3.11/site-packages/werkzeug/serving.py", line 324, in execute
    application_iter = app(environ, start_response)
                       ^^^^^^^^^^^^^^^^^^^^^^^^^^^^
  File "/home/self-clearing/venv/lib/python3.11/site-packages/flask/app.py", line 1498, in __call__
    return self.wsgi_app(environ, start_response)
           ^^^^^^^^^^^^^^^^^^^^^^^^^^^^^^^^^^^^^^
  File "/home/self-clearing/venv/lib/python3.11/site-packages/flask_socketio/__init__.py", line 43, in __call__
    return super(_SocketIOMiddleware, self).__call__(environ,
           ^^^^^^^^^^^^^^^^^^^^^^^^^^^^^^^^^^^^^^^^^^^^^^^^^^
  File "/home/self-clearing/venv/lib/python3.11/site-packages/engineio/middleware.py", line 63, in __call__
    return self.engineio_app.handle_request(environ, start_response)
           ^^^^^^^^^^^^^^^^^^^^^^^^^^^^^^^^^^^^^^^^^^^^^^^^^^^^^^^^^
  File "/home/self-clearing/venv/lib/python3.11/site-packages/socketio/server.py", line 433, in handle_request
    return self.eio.handle_request(environ, start_response)
           ^^^^^^^^^^^^^^^^^^^^^^^^^^^^^^^^^^^^^^^^^^^^^^^^
  File "/home/self-clearing/venv/lib/python3.11/site-packages/engineio/server.py", line 272, in handle_request
    socket = self._get_socket(sid)
             ^^^^^^^^^^^^^^^^^^^^^
  File "/home/self-clearing/venv/lib/python3.11/site-packages/engineio/base_server.py", line 229, in _get_socket
    raise KeyError('Session is disconnected')
KeyError: 'Session is disconnected'  
2025-03-24 13:05:16.164 [ERROR]  werkzeug                        Error on request:
Traceback (most recent call last):
  File "/home/self-clearing/venv/lib/python3.11/site-packages/werkzeug/serving.py", line 363, in run_wsgi
    execute(self.server.app)
  File "/home/self-clearing/venv/lib/python3.11/site-packages/werkzeug/serving.py", line 324, in execute
    application_iter = app(environ, start_response)
                       ^^^^^^^^^^^^^^^^^^^^^^^^^^^^
  File "/home/self-clearing/venv/lib/python3.11/site-packages/flask/app.py", line 1498, in __call__
    return self.wsgi_app(environ, start_response)
           ^^^^^^^^^^^^^^^^^^^^^^^^^^^^^^^^^^^^^^
  File "/home/self-clearing/venv/lib/python3.11/site-packages/flask_socketio/__init__.py", line 43, in __call__
    return super(_SocketIOMiddleware, self).__call__(environ,
           ^^^^^^^^^^^^^^^^^^^^^^^^^^^^^^^^^^^^^^^^^^^^^^^^^^
  File "/home/self-clearing/venv/lib/python3.11/site-packages/engineio/middleware.py", line 63, in __call__
    return self.engineio_app.handle_request(environ, start_response)
           ^^^^^^^^^^^^^^^^^^^^^^^^^^^^^^^^^^^^^^^^^^^^^^^^^^^^^^^^^
  File "/home/self-clearing/venv/lib/python3.11/site-packages/socketio/server.py", line 433, in handle_request
    return self.eio.handle_request(environ, start_response)
           ^^^^^^^^^^^^^^^^^^^^^^^^^^^^^^^^^^^^^^^^^^^^^^^^
  File "/home/self-clearing/venv/lib/python3.11/site-packages/engineio/server.py", line 272, in handle_request
    socket = self._get_socket(sid)
             ^^^^^^^^^^^^^^^^^^^^^
  File "/home/self-clearing/venv/lib/python3.11/site-packages/engineio/base_server.py", line 229, in _get_socket
    raise KeyError('Session is disconnected')
KeyError: 'Session is disconnected'  
2025-03-24 13:44:38.341 [ERROR]  werkzeug                        Error on request:
Traceback (most recent call last):
  File "/home/self-clearing/venv/lib/python3.11/site-packages/werkzeug/serving.py", line 363, in run_wsgi
    execute(self.server.app)
  File "/home/self-clearing/venv/lib/python3.11/site-packages/werkzeug/serving.py", line 326, in execute
    for data in application_iter:
  File "/home/self-clearing/venv/lib/python3.11/site-packages/werkzeug/wsgi.py", line 256, in __next__
    return self._next()
           ^^^^^^^^^^^^
  File "/home/self-clearing/venv/lib/python3.11/site-packages/werkzeug/wrappers/response.py", line 32, in _iter_encoded
    for item in iterable:
  File "/home/self-clearing/Self_Clearing_Server/server/microscope_camera_control.py", line 49, in yield_frame
    yield (b"--frame\r\n" b"Content-Type: image/jpeg\r\n\r\n" + self.frame_to_display + b"\r\n")
           ^^^^^^^^^^^^^^^^^^^^^^^^^^^^^^^^^^^^^^^^^^^^^^^^^^^^^^^^^^^^^^^^^^^^^^^^^^^^^^^^^^^^^
TypeError: can't concat NoneType to bytes  
