2025-03-25 11:42:27.472 [ERROR]  werkzeug                        Error on request:
Traceback (most recent call last):
  File "/home/self-clearing/venv/lib/python3.11/site-packages/werkzeug/serving.py", line 363, in run_wsgi
    execute(self.server.app)
  File "/home/self-clearing/venv/lib/python3.11/site-packages/werkzeug/serving.py", line 326, in execute
    for data in application_iter:
  File "/home/self-clearing/venv/lib/python3.11/site-packages/werkzeug/wsgi.py", line 256, in __next__
    return self._next()
           ^^^^^^^^^^^^
  File "/home/self-clearing/venv/lib/python3.11/site-packages/werkzeug/wrappers/response.py", line 32, in _iter_encoded
    for item in iterable:
  File "/home/self-clearing/Self_Clearing_Server/server/microscope_camera_control.py", line 49, in yield_frame
    yield (b"--frame\r\n" b"Content-Type: image/jpeg\r\n\r\n" + self.frame_to_display + b"\r\n")
           ^^^^^^^^^^^^^^^^^^^^^^^^^^^^^^^^^^^^^^^^^^^^^^^^^^^^^^^^^^^^^^^^^^^^^^^^^^^^^^^^^^^^^
TypeError: can't concat NoneType to bytes  
2025-03-25 11:45:31.224 [ERROR]  werkzeug                        Error on request:
Traceback (most recent call last):
  File "/home/self-clearing/venv/lib/python3.11/site-packages/werkzeug/serving.py", line 363, in run_wsgi
    execute(self.server.app)
  File "/home/self-clearing/venv/lib/python3.11/site-packages/werkzeug/serving.py", line 326, in execute
    for data in application_iter:
  File "/home/self-clearing/venv/lib/python3.11/site-packages/werkzeug/wsgi.py", line 256, in __next__
    return self._next()
           ^^^^^^^^^^^^
  File "/home/self-clearing/venv/lib/python3.11/site-packages/werkzeug/wrappers/response.py", line 32, in _iter_encoded
    for item in iterable:
  File "/home/self-clearing/Self_Clearing_Server/server/microscope_camera_control.py", line 49, in yield_frame
    yield (b"--frame\r\n" b"Content-Type: image/jpeg\r\n\r\n" + self.frame_to_display + b"\r\n")
           ^^^^^^^^^^^^^^^^^^^^^^^^^^^^^^^^^^^^^^^^^^^^^^^^^^^^^^^^^^^^^^^^^^^^^^^^^^^^^^^^^^^^^
TypeError: can't concat NoneType to bytes  
2025-03-25 11:46:06.668 [ERROR]  werkzeug                        Error on request:
Traceback (most recent call last):
  File "/home/self-clearing/venv/lib/python3.11/site-packages/werkzeug/serving.py", line 363, in run_wsgi
    execute(self.server.app)
  File "/home/self-clearing/venv/lib/python3.11/site-packages/werkzeug/serving.py", line 326, in execute
    for data in application_iter:
  File "/home/self-clearing/venv/lib/python3.11/site-packages/werkzeug/wsgi.py", line 256, in __next__
    return self._next()
           ^^^^^^^^^^^^
  File "/home/self-clearing/venv/lib/python3.11/site-packages/werkzeug/wrappers/response.py", line 32, in _iter_encoded
    for item in iterable:
  File "/home/self-clearing/Self_Clearing_Server/server/microscope_camera_control.py", line 49, in yield_frame
    yield (b"--frame\r\n" b"Content-Type: image/jpeg\r\n\r\n" + self.frame_to_display + b"\r\n")
           ^^^^^^^^^^^^^^^^^^^^^^^^^^^^^^^^^^^^^^^^^^^^^^^^^^^^^^^^^^^^^^^^^^^^^^^^^^^^^^^^^^^^^
TypeError: can't concat NoneType to bytes  
2025-03-25 11:46:25.243 [ERROR]  werkzeug                        Error on request:
Traceback (most recent call last):
  File "/home/self-clearing/venv/lib/python3.11/site-packages/werkzeug/serving.py", line 363, in run_wsgi
    execute(self.server.app)
  File "/home/self-clearing/venv/lib/python3.11/site-packages/werkzeug/serving.py", line 326, in execute
    for data in application_iter:
  File "/home/self-clearing/venv/lib/python3.11/site-packages/werkzeug/wsgi.py", line 256, in __next__
    return self._next()
           ^^^^^^^^^^^^
  File "/home/self-clearing/venv/lib/python3.11/site-packages/werkzeug/wrappers/response.py", line 32, in _iter_encoded
    for item in iterable:
  File "/home/self-clearing/Self_Clearing_Server/server/microscope_camera_control.py", line 49, in yield_frame
    yield (b"--frame\r\n" b"Content-Type: image/jpeg\r\n\r\n" + self.frame_to_display + b"\r\n")
           ^^^^^^^^^^^^^^^^^^^^^^^^^^^^^^^^^^^^^^^^^^^^^^^^^^^^^^^^^^^^^^^^^^^^^^^^^^^^^^^^^^^^^
TypeError: can't concat NoneType to bytes  
2025-03-25 11:46:34.574 [ERROR]  werkzeug                        Error on request:
Traceback (most recent call last):
  File "/home/self-clearing/venv/lib/python3.11/site-packages/werkzeug/serving.py", line 363, in run_wsgi
    execute(self.server.app)
  File "/home/self-clearing/venv/lib/python3.11/site-packages/werkzeug/serving.py", line 326, in execute
    for data in application_iter:
  File "/home/self-clearing/venv/lib/python3.11/site-packages/werkzeug/wsgi.py", line 256, in __next__
    return self._next()
           ^^^^^^^^^^^^
  File "/home/self-clearing/venv/lib/python3.11/site-packages/werkzeug/wrappers/response.py", line 32, in _iter_encoded
    for item in iterable:
  File "/home/self-clearing/Self_Clearing_Server/server/microscope_camera_control.py", line 49, in yield_frame
    yield (b"--frame\r\n" b"Content-Type: image/jpeg\r\n\r\n" + self.frame_to_display + b"\r\n")
           ^^^^^^^^^^^^^^^^^^^^^^^^^^^^^^^^^^^^^^^^^^^^^^^^^^^^^^^^^^^^^^^^^^^^^^^^^^^^^^^^^^^^^
TypeError: can't concat NoneType to bytes  
2025-03-25 12:02:12.030 [ERROR]  werkzeug                        Error on request:
Traceback (most recent call last):
  File "/home/self-clearing/venv/lib/python3.11/site-packages/werkzeug/serving.py", line 363, in run_wsgi
    execute(self.server.app)
  File "/home/self-clearing/venv/lib/python3.11/site-packages/werkzeug/serving.py", line 326, in execute
    for data in application_iter:
  File "/home/self-clearing/venv/lib/python3.11/site-packages/werkzeug/wsgi.py", line 256, in __next__
    return self._next()
           ^^^^^^^^^^^^
  File "/home/self-clearing/venv/lib/python3.11/site-packages/werkzeug/wrappers/response.py", line 32, in _iter_encoded
    for item in iterable:
  File "/home/self-clearing/Self_Clearing_Server/server/microscope_camera_control.py", line 47, in yield_frame
    while(self.camera_1.isOpened()):
          ^^^^^^^^^^^^^^^^^^^^^^^^^^
AttributeError: 'NoneType' object has no attribute 'isOpened'  
2025-03-25 12:02:33.638 [ERROR]  werkzeug                        Error on request:
Traceback (most recent call last):
  File "/home/self-clearing/venv/lib/python3.11/site-packages/werkzeug/serving.py", line 363, in run_wsgi
    execute(self.server.app)
  File "/home/self-clearing/venv/lib/python3.11/site-packages/werkzeug/serving.py", line 326, in execute
    for data in application_iter:
  File "/home/self-clearing/venv/lib/python3.11/site-packages/werkzeug/wsgi.py", line 256, in __next__
    return self._next()
           ^^^^^^^^^^^^
  File "/home/self-clearing/venv/lib/python3.11/site-packages/werkzeug/wrappers/response.py", line 32, in _iter_encoded
    for item in iterable:
  File "/home/self-clearing/Self_Clearing_Server/server/microscope_camera_control.py", line 47, in yield_frame
    while(self.camera_1.isOpened()):
          ^^^^^^^^^^^^^^^^^^^^^^^^^^
AttributeError: 'NoneType' object has no attribute 'isOpened'  
2025-03-25 12:06:38.686 [ERROR]  werkzeug                        Error on request:
Traceback (most recent call last):
  File "/home/self-clearing/venv/lib/python3.11/site-packages/werkzeug/serving.py", line 363, in run_wsgi
    execute(self.server.app)
  File "/home/self-clearing/venv/lib/python3.11/site-packages/werkzeug/serving.py", line 326, in execute
    for data in application_iter:
  File "/home/self-clearing/venv/lib/python3.11/site-packages/werkzeug/wsgi.py", line 256, in __next__
    return self._next()
           ^^^^^^^^^^^^
  File "/home/self-clearing/venv/lib/python3.11/site-packages/werkzeug/wrappers/response.py", line 32, in _iter_encoded
    for item in iterable:
  File "/home/self-clearing/Self_Clearing_Server/server/microscope_camera_control.py", line 51, in yield_frame
    while(self.camera_1.isOpened()):
          ^^^^^^^^^^^^^^^^^^^^^^^^^^
AttributeError: 'NoneType' object has no attribute 'isOpened'  
2025-03-25 12:08:15.247 [ERROR]  werkzeug                        Error on request:
Traceback (most recent call last):
  File "/home/self-clearing/venv/lib/python3.11/site-packages/werkzeug/serving.py", line 363, in run_wsgi
    execute(self.server.app)
  File "/home/self-clearing/venv/lib/python3.11/site-packages/werkzeug/serving.py", line 326, in execute
    for data in application_iter:
  File "/home/self-clearing/venv/lib/python3.11/site-packages/werkzeug/wsgi.py", line 256, in __next__
    return self._next()
           ^^^^^^^^^^^^
  File "/home/self-clearing/venv/lib/python3.11/site-packages/werkzeug/wrappers/response.py", line 32, in _iter_encoded
    for item in iterable:
  File "/home/self-clearing/Self_Clearing_Server/server/microscope_camera_control.py", line 52, in yield_frame
    if (camera_1 == None):
        ^^^^^^^^^^^^^^^^^^
NameError: name 'camera_1' is not defined  
2025-03-25 12:08:23.149 [ERROR]  werkzeug                        Error on request:
Traceback (most recent call last):
  File "/home/self-clearing/venv/lib/python3.11/site-packages/werkzeug/serving.py", line 363, in run_wsgi
    execute(self.server.app)
  File "/home/self-clearing/venv/lib/python3.11/site-packages/werkzeug/serving.py", line 326, in execute
    for data in application_iter:
  File "/home/self-clearing/venv/lib/python3.11/site-packages/werkzeug/wsgi.py", line 256, in __next__
    return self._next()
           ^^^^^^^^^^^^
  File "/home/self-clearing/venv/lib/python3.11/site-packages/werkzeug/wrappers/response.py", line 32, in _iter_encoded
    for item in iterable:
  File "/home/self-clearing/Self_Clearing_Server/server/microscope_camera_control.py", line 52, in yield_frame
    if (self.camera_1 == None):
        ^^^^^^^^^^^^^^^^^^^^^^^
NameError: name 'camera_1' is not defined  
2025-03-25 12:08:32.617 [ERROR]  werkzeug                        Error on request:
Traceback (most recent call last):
  File "/home/self-clearing/venv/lib/python3.11/site-packages/werkzeug/serving.py", line 363, in run_wsgi
    execute(self.server.app)
  File "/home/self-clearing/venv/lib/python3.11/site-packages/werkzeug/serving.py", line 326, in execute
    for data in application_iter:
  File "/home/self-clearing/venv/lib/python3.11/site-packages/werkzeug/wsgi.py", line 256, in __next__
    return self._next()
           ^^^^^^^^^^^^
  File "/home/self-clearing/venv/lib/python3.11/site-packages/werkzeug/wrappers/response.py", line 32, in _iter_encoded
    for item in iterable:
  File "/home/self-clearing/Self_Clearing_Server/server/microscope_camera_control.py", line 53, in yield_frame
    while(self.camera_1.isOpened()):
          ^^^^^^^^^^^^^^^^^^^^^^^^^^
AttributeError: 'NoneType' object has no attribute 'isOpened'  
2025-03-25 12:08:51.644 [ERROR]  werkzeug                        Error on request:
Traceback (most recent call last):
  File "/home/self-clearing/venv/lib/python3.11/site-packages/engineio/async_drivers/_websocket_wsgi.py", line 26, in send
    return self.ws.send(message)
           ^^^^^^^^^^^^^^^^^^^^^
  File "/home/self-clearing/venv/lib/python3.11/site-packages/simple_websocket/ws.py", line 78, in send
    raise ConnectionClosed(self.close_reason, self.close_message)
simple_websocket.errors.ConnectionClosed: Connection closed: 1001 

During handling of the above exception, another exception occurred:

Traceback (most recent call last):
  File "/home/self-clearing/venv/lib/python3.11/site-packages/werkzeug/serving.py", line 363, in run_wsgi
    execute(self.server.app)
  File "/home/self-clearing/venv/lib/python3.11/site-packages/werkzeug/serving.py", line 324, in execute
    application_iter = app(environ, start_response)
                       ^^^^^^^^^^^^^^^^^^^^^^^^^^^^
  File "/home/self-clearing/venv/lib/python3.11/site-packages/flask/app.py", line 1498, in __call__
    return self.wsgi_app(environ, start_response)
           ^^^^^^^^^^^^^^^^^^^^^^^^^^^^^^^^^^^^^^
  File "/home/self-clearing/venv/lib/python3.11/site-packages/flask_socketio/__init__.py", line 43, in __call__
    return super(_SocketIOMiddleware, self).__call__(environ,
           ^^^^^^^^^^^^^^^^^^^^^^^^^^^^^^^^^^^^^^^^^^^^^^^^^^
  File "/home/self-clearing/venv/lib/python3.11/site-packages/engineio/middleware.py", line 63, in __call__
    return self.engineio_app.handle_request(environ, start_response)
           ^^^^^^^^^^^^^^^^^^^^^^^^^^^^^^^^^^^^^^^^^^^^^^^^^^^^^^^^^
  File "/home/self-clearing/venv/lib/python3.11/site-packages/socketio/server.py", line 433, in handle_request
    return self.eio.handle_request(environ, start_response)
           ^^^^^^^^^^^^^^^^^^^^^^^^^^^^^^^^^^^^^^^^^^^^^^^^
  File "/home/self-clearing/venv/lib/python3.11/site-packages/engineio/server.py", line 274, in handle_request
    packets = socket.handle_get_request(
              ^^^^^^^^^^^^^^^^^^^^^^^^^^
  File "/home/self-clearing/venv/lib/python3.11/site-packages/engineio/socket.py", line 90, in handle_get_request
    return getattr(self, '_upgrade_' + transport)(environ,
           ^^^^^^^^^^^^^^^^^^^^^^^^^^^^^^^^^^^^^^^^^^^^^^^
  File "/home/self-clearing/venv/lib/python3.11/site-packages/engineio/socket.py", line 146, in _upgrade_websocket
    return ws(environ, start_response)
           ^^^^^^^^^^^^^^^^^^^^^^^^^^^
  File "/home/self-clearing/venv/lib/python3.11/site-packages/engineio/async_drivers/_websocket_wsgi.py", line 15, in __call__
    ret = self.app(self)
          ^^^^^^^^^^^^^^
  File "/home/self-clearing/venv/lib/python3.11/site-packages/engineio/socket.py", line 175, in _websocket_handler
    ws.send(packet.Packet(packet.PONG, data='probe').encode())
  File "/home/self-clearing/venv/lib/python3.11/site-packages/engineio/async_drivers/_websocket_wsgi.py", line 28, in send
    raise IOError()
OSError  
2025-03-25 12:10:22.159 [ERROR]  werkzeug                        Error on request:
Traceback (most recent call last):
  File "/home/self-clearing/venv/lib/python3.11/site-packages/werkzeug/serving.py", line 363, in run_wsgi
    execute(self.server.app)
  File "/home/self-clearing/venv/lib/python3.11/site-packages/werkzeug/serving.py", line 326, in execute
    for data in application_iter:
  File "/home/self-clearing/venv/lib/python3.11/site-packages/werkzeug/wsgi.py", line 256, in __next__
    return self._next()
           ^^^^^^^^^^^^
  File "/home/self-clearing/venv/lib/python3.11/site-packages/werkzeug/wrappers/response.py", line 32, in _iter_encoded
    for item in iterable:
  File "/home/self-clearing/Self_Clearing_Server/server/microscope_camera_control.py", line 52, in yield_frame
    yield (b"--frame\r\n" b"Content-Type: image/jpeg\r\n\r\n" + self.frame_to_display + b"\r\n")
           ^^^^^^^^^^^^^^^^^^^^^^^^^^^^^^^^^^^^^^^^^^^^^^^^^^^^^^^^^^^^^^^^^^^^^^^^^^^^^^^^^^^^^
TypeError: can't concat NoneType to bytes  
2025-03-25 12:10:36.835 [ERROR]  werkzeug                        Error on request:
Traceback (most recent call last):
  File "/home/self-clearing/venv/lib/python3.11/site-packages/werkzeug/serving.py", line 363, in run_wsgi
    execute(self.server.app)
  File "/home/self-clearing/venv/lib/python3.11/site-packages/werkzeug/serving.py", line 326, in execute
    for data in application_iter:
  File "/home/self-clearing/venv/lib/python3.11/site-packages/werkzeug/wsgi.py", line 256, in __next__
    return self._next()
           ^^^^^^^^^^^^
  File "/home/self-clearing/venv/lib/python3.11/site-packages/werkzeug/wrappers/response.py", line 32, in _iter_encoded
    for item in iterable:
  File "/home/self-clearing/Self_Clearing_Server/server/microscope_camera_control.py", line 52, in yield_frame
    yield (b"--frame\r\n" b"Content-Type: image/jpeg\r\n\r\n" + self.frame_to_display + b"\r\n")
           ^^^^^^^^^^^^^^^^^^^^^^^^^^^^^^^^^^^^^^^^^^^^^^^^^^^^^^^^^^^^^^^^^^^^^^^^^^^^^^^^^^^^^
TypeError: can't concat NoneType to bytes  
2025-03-25 12:11:07.658 [ERROR]  werkzeug                        Error on request:
Traceback (most recent call last):
  File "/home/self-clearing/venv/lib/python3.11/site-packages/werkzeug/serving.py", line 363, in run_wsgi
    execute(self.server.app)
  File "/home/self-clearing/venv/lib/python3.11/site-packages/werkzeug/serving.py", line 326, in execute
    for data in application_iter:
  File "/home/self-clearing/venv/lib/python3.11/site-packages/werkzeug/wsgi.py", line 256, in __next__
    return self._next()
           ^^^^^^^^^^^^
  File "/home/self-clearing/venv/lib/python3.11/site-packages/werkzeug/wrappers/response.py", line 32, in _iter_encoded
    for item in iterable:
  File "/home/self-clearing/Self_Clearing_Server/server/microscope_camera_control.py", line 52, in yield_frame
    yield (b"--frame\r\n" b"Content-Type: image/jpeg\r\n\r\n" + self.frame_to_display + b"\r\n")
           ^^^^^^^^^^^^^^^^^^^^^^^^^^^^^^^^^^^^^^^^^^^^^^^^^^^^^^^^^^^^^^^^^^^^^^^^^^^^^^^^^^^^^
TypeError: can't concat NoneType to bytes  
2025-03-25 13:24:25.681 [ERROR]  werkzeug                        Error on request:
Traceback (most recent call last):
  File "/home/self-clearing/venv/lib/python3.11/site-packages/werkzeug/serving.py", line 363, in run_wsgi
    execute(self.server.app)
  File "/home/self-clearing/venv/lib/python3.11/site-packages/werkzeug/serving.py", line 326, in execute
    for data in application_iter:
  File "/home/self-clearing/venv/lib/python3.11/site-packages/werkzeug/wsgi.py", line 256, in __next__
    return self._next()
           ^^^^^^^^^^^^
  File "/home/self-clearing/venv/lib/python3.11/site-packages/werkzeug/wrappers/response.py", line 32, in _iter_encoded
    for item in iterable:
  File "/home/self-clearing/Self_Clearing_Server/server/microscope_camera_control.py", line 53, in yield_frame
    yield (b"--frame\r\n" b"Content-Type: image/jpeg\r\n\r\n" + self.frame_to_display + b"\r\n")
           ^^^^^^^^^^^^^^^^^^^^^^^^^^^^^^^^^^^^^^^^^^^^^^^^^^^^^^^^^^^^^^^^^^^^^^^^^^^^^^^^^^^^^
TypeError: can't concat str to bytes  
2025-03-25 13:29:14.675 [ERROR]  werkzeug                        Error on request:
Traceback (most recent call last):
  File "/home/self-clearing/venv/lib/python3.11/site-packages/werkzeug/serving.py", line 363, in run_wsgi
    execute(self.server.app)
  File "/home/self-clearing/venv/lib/python3.11/site-packages/werkzeug/serving.py", line 326, in execute
    for data in application_iter:
  File "/home/self-clearing/venv/lib/python3.11/site-packages/werkzeug/wsgi.py", line 256, in __next__
    return self._next()
           ^^^^^^^^^^^^
  File "/home/self-clearing/venv/lib/python3.11/site-packages/werkzeug/wrappers/response.py", line 32, in _iter_encoded
    for item in iterable:
  File "/home/self-clearing/Self_Clearing_Server/server/microscope_camera_control.py", line 53, in yield_frame
    yield (b"--frame\r\n" b"Content-Type: image/jpeg\r\n\r\n" + self.frame_to_display + b"\r\n")
           ^^^^^^^^^^^^^^^^^^^^^^^^^^^^^^^^^^^^^^^^^^^^^^^^^^^^^^^^^^^^^^^^^^^^^^^^^^^^^^^^^^^^^
numpy._core._exceptions._UFuncNoLoopError: ufunc 'add' did not contain a loop with signature matching types (dtype('S37'), dtype('uint8')) -> None  
